Workbook

Sheet 1. INSTRUCCIONES
B1: UNIVERSIDAD DE INVESTIGACIÓN DE TECNOLOGÍA EXPERIMENTAL YACHAY TECH
B2: DIRECCIÓN GENERAL DE POSGRADOS
A3: Esta Plantilla aplica para los Programas de Posgrado. El objetivo es obtener el valor de arancel, matrícula y cohorte mínima, luego de ingresar la información pertinente al programa según se detalla en el siguiente cuadro.
A6: Hojas de Cálculo | B6: Celdas Habilitadas | C6: Detalle de Campos
A7: 2. COSTOS PERSONAL | B7: B1:C1 | C7: Nombre del Programa Propuesto o Aprobado por el CES
B8: B2 | C8: Duración del Programa en Número de Períodos Académicos (o semestres)
B9: B3 | C9: Porcentaje de presencialidad:
B10: B12, D9:E12 | C10: Personal administrativo requerido.
B11: A18:G55 | C11: Se ingresa las asignaturas por nivel (excepto las de Titulación): - El código (Columna B) y nombre de asignatura (Columna C), - Número de horas según Malla Curricular (Columnas E, F, G ) - Lista desplegable elegir Tipo de Profesor (Columna D)
B12: B59: E63 | C12: Detalle de las asignaturas de titulación, con la misma estructura del rango anterior.
A13: 3. COSTOS INFRAESTRUCTURA | B13: B32 | C13: Número de aulas requeridas para el Programa
A14: 4. CÁLCULO | B14: B6:B11 | C14: Costos Fijos del Programa
B15: B15, B17 | C15: Costos Variables del Programa
B16: B20 | C16: Precio referencial de mercado
B17: B21 | C17: Precio del programa por estudiante (menor o igual al precio de mercado)
A19: Nota: Solo Llenar las celdas de color cyan en todas las hojas de calculo.

Sheet 2. COSTOS PERSONAL
A1: NOMBRE DEL PROGRAMA:
A2: Duración del Programa (No. PAOs) | C2: =$B$2*6 -> 0
A3: Porcentaje de presencialidad (%P) | C3: =1-B3 -> 1
A5: PERSONAL
A6: Personal | B6: Remuneración mensual | C6: Valor Hora | D6: Cantidad | E6: Horas mensuales | F6: Costo Personal Adminsitrativo (CPAdi)
A7: Profesor Magister | B7: 2034 | C7: =B7/160 -> 12.7125
A8: Profesor Doctor | B8: 2650.36 | C8: =B8/160 -> 16.56475
A9: Coordinador | D9: 1 | F9: =D9*(E9*$C$2)*C7 -> 0
A10: Secretaria | B10: 733 | C10: =B10/160 -> 4.58125 | F10: =D10*(E10*$C$2)*C10 -> 0
A11: Técnico | B11: 986 | C11: =B11/160 -> 6.1625 | F11: =D11*(E11*$C$2)*C11 -> 0
A12: Otros | C12: =B12/160 -> 0 | F12: =D12*(E12*$C$2)*C12 -> 0
A13: TOTAL COSTO PERSONAL ADMINISTRATIVO | F13: =SUM(F9:F12) -> 0 | G13: COSTO FIJO
A15: PERSONAL ACADÉMICO
A16: ASIGNATURA | B16: Tipo Profesor | C16: HCD | D16: HAP | E16: HAA | F16: Costo Asignatura (CAi)
A17: Primer Nivel
B18: Profesor Magister | F18: =(C18+D18)*1.6*IF(B18=$A$7,$C$7,$C$8) -> 0
B19: Profesor Doctor | F19: =(C19+D19)*1.6*IF(B19=$A$7,$C$7,$C$8) -> 0
F20: =(C20+D20)*1.6*IF(B20=$A$7,$C$7,$C$8) -> 0
F21: =(C21+D21)*1.6*IF(B21=$A$7,$C$7,$C$8) -> 0
F22: =(C22+D22)*1.6*IF(B22=$A$7,$C$7,$C$8) -> 0
F23: =(C23+D23)*1.6*IF(B23=$A$7,$C$7,$C$8) -> 0
F24: =(C24+D24)*1.6*IF(B24=$A$7,$C$7,$C$8) -> 0
F25: =(C25+D25)*1.6*IF(B25=$A$7,$C$7,$C$8) -> 0
A26: SUBTOTAL PRIMER NIVEL | C26: =SUM(C18:C25) -> 0 | D26: =SUM(D18:D25) -> 0 | F26: =SUM(F18:F25) -> 0
A27: Segundo Nivel
F28: =(C28+D28)*1.6*IF(B28=$A$7,$C$7,$C$8) -> 0
F29: =(C29+D29)*1.6*IF(B29=$A$7,$C$7,$C$8) -> 0
F30: =(C30+D30)*1.6*IF(B30=$A$7,$C$7,$C$8) -> 0
F31: =(C31+D31)*1.6*IF(B31=$A$7,$C$7,$C$8) -> 0
F32: =(C32+D32)*1.6*IF(B32=$A$7,$C$7,$C$8) -> 0
F33: =(C33+D33)*1.6*IF(B33=$A$7,$C$7,$C$8) -> 0
F34: =(C34+D34)*1.6*IF(B34=$A$7,$C$7,$C$8) -> 0
F35: =(C35+D35)*1.6*IF(B35=$A$7,$C$7,$C$8) -> 0
A36: SUBTOTAL SEGUNDO NIVEL | C36: =SUM(C28:C35) -> 0 | D36: =SUM(D28:D35) -> 0 | F36: =SUM(F28:F35) -> 0
A37: Tercer Nivel
F38: =(C38+D38)*1.6*IF(B38=$A$7,$C$7,$C$8) -> 0
F39: =(C39+D39)*1.6*IF(B39=$A$7,$C$7,$C$8) -> 0
F40: =(C40+D40)*1.6*IF(B40=$A$7,$C$7,$C$8) -> 0
F41: =(C41+D41)*1.6*IF(B41=$A$7,$C$7,$C$8) -> 0
F42: =(C42+D42)*1.6*IF(B42=$A$7,$C$7,$C$8) -> 0
...

Sheet 3. COSTOS INFRAESTRUCTURA
A1: INFRAESTRUCTURA-BIENES-2023
A2: DESCRIPCIÓN | B2: PAGADO
A3: Agua Potable | B3: 4389.99
A4: Energia Electrica | B4: 78684.97
A5: Seguridad | B5: 343870.04
A6: Aseo | B6: 395940.94
A7: Telecomunicaciones | B7: 246474.18
A8: Edificios, Locales, Residencias y Cableado Estructurado (Instalación, Mantenimiento y Reparación) | B8: 8437.5
A9: Mantenimiento de Areas Verdes y Arreglo de Vias Internas | B9: 21056.35
A10: Total (CABI) | B10: =SUM(B3:B9) -> 1098854
A11: INFRAESTRUCTURA TECNOLÓGICA-2023
A12: Red Avanzada | B12: 140499.36
A13: Data Center Virtual | B13: 61678.3
A14: Mantenimiento centros de datos y equipos de switch | B14: 18586.5
A15: Virtualización Data Center Hiperconvergent | B15: 9989
A16: Office | B16: 6278.8
A17: Firewall | B17: 20338.51
A18: Antivirus | B18: 6300
A19: Sistema de respaldos | B19: 31920
A20: Koha | B20: 1166.67
A21: DSpace | B21: 1333.33
A22: Scopus | B22: 18958
A23: Scifinder y digitalia | B23: 15287
A24: Herramienta antiplagio compilatio | B24: 4520
A25: Total (CAIT) | B25: =SUM(B12:B24) -> 336855.47
A27: DESCRIPCIÓN | B27: CANTIDAD
A28: Aulas + Laboratorios (NTA) | B28: 65
A29: Personas UITEY (NTP) | B29: 2072
A30: Costo Bienes e Infraestructuta por Aula por Hora (CBIAH) | B30: =B10/(365*24*B28) -> 1.9298454
A31: Costo Infraestructuta Tecnológica por Persona por Hora (CITPH) | B31: =B25/(365*24*B29) -> 0.018558794
A32: N° Aulas + Laboratorios para el Programa (NA)
A33: Costo de bienes e infraestructura (CTBI) | B33: =B30*B32*('2. COSTOS PERSONAL'!C65+'2. COSTOS PERSONAL'!D65)*'2. COSTOS PERSONAL'!B3 -> 0 | C33: COSTO FIJO
A34: Costo Infraestructuta Tecnológica por Persona (CTITP) | B34: =B31*('2. COSTOS PERSONAL'!C65+'2. COSTOS PERSONAL'!D65)*(1-'2. COSTOS PERSONAL'!B3) -> 0 | C34: COSTO VARIABLE

Sheet 4. CÁLCULO
A1: COSTO DEL PROGRAMA
A2: Costos Fijos | B2: Total (USD)
A3: Costo personal académico (CTPA) | B3: =+'2. COSTOS PERSONAL'!F57 -> 0
A4: Costo personal administrativo (CTPAd) | B4: ='2. COSTOS PERSONAL'!F13 -> 0
A5: Costo bienes e infraestructura (CTBI) | B5: ='3. COSTOS INFRAESTRUCTURA'!B33 -> 0
A6: Otros costos de bienes e infraestructura
A7: Costo Publicidad
A8: Becas
A9: Ayudas económicas
A10: Deserción
A11: Otros costos fijos asociados al programa
A12: Subtotal | B12: =SUM(B3:B11) -> 0 | C12: Total Costos Fijos (CF)
A13: Costos Variables | B13: Total (USD)
A14: Personal Académico - Unidad de Titulación - por estudiante | B14: =+'2. COSTOS PERSONAL'!F70 -> 331.295
A15: Costo reactivos/materiales por estudiante
A16: ='3. COSTOS INFRAESTRUCTURA'!A34 -> Costo Infraestructuta Tecnológica por Persona (CTITP) | B16: ='3. COSTOS INFRAESTRUCTURA'!B34 -> 0
A17: Otros costos variables asociados al programa por estudiante
A18: Subtotal | B18: =SUM(B14:B17) -> 331.295 | C18: Total Costos Variables (CV)
A20: Precio de Mercado
A21: Costo sugerido del programa por estudiante
A22: Número de Estudiantes (tamaño mínimo de la cohorte) | B22: =INT(B12/(B21-B18)) -> 0
A23: Costo total del programa (CT) | B23: =B12+B22*B18 -> 0
A24: Arancel | B24: =B23/B22 -> #DIV/0!
A25: Matrícula (10% del arancel) | B25: =B24*10% -> #DIV/0!
A26: Matrícula + Arancel | B26: =SUM(B24:B25) -> #DIV/0!
A27: Inscripción (1% de matrícula + arancel) | B27: =1%*B26 -> #DIV/0!
A28: Arancel + matrícula + inscripción | B28: =B24+B25+B27 -> #DIV/0!
A30: N° de Estudiantes | B30: Costos del Programa | C30: Ingresos x Matrícula + Arancel
A31: 0 | B31: =$B$18*A31+$B$12 -> 0 | C31: =$B$26*$A31 -> #DIV/0!
A32: =A31+1 -> 1 | B32: =$B$18*A32+$B$12 -> 331.295 | C32: =$B$26*$A32 -> #DIV/0!
A33: =A32+1 -> 2 | B33: =$B$18*A33+$B$12 -> 662.59 | C33: =$B$26*$A33 -> #DIV/0!
A34: =A33+1 -> 3 | B34: =$B$18*A34+$B$12 -> 993.885 | C34: =$B$26*$A34 -> #DIV/0!
A35: =A34+1 -> 4 | B35: =$B$18*A35+$B$12 -> 1325.18 | C35: =$B$26*$A35 -> #DIV/0!
A36: =A35+1 -> 5 | B36: =$B$18*A36+$B$12 -> 1656.475 | C36: =$B$26*$A36 -> #DIV/0!
A37: =A36+1 -> 6 | B37: =$B$18*A37+$B$12 -> 1987.77 | C37: =$B$26*$A37 -> #DIV/0!
A38: =A37+1 -> 7 | B38: =$B$18*A38+$B$12 -> 2319.065 | C38: =$B$26*$A38 -> #DIV/0!
A39: =A38+1 -> 8 | B39: =$B$18*A39+$B$12 -> 2650.36 | C39: =$B$26*$A39 -> #DIV/0!
A40: =A39+1 -> 9 | B40: =$B$18*A40+$B$12 -> 2981.655 | C40: =$B$26*$A40 -> #DIV/0!
A41: =A40+1 -> 10 | B41: =$B$18*A41+$B$12 -> 3312.95 | C41: =$B$26*$A41 -> #DIV/0!
A42: =A41+1 -> 11 | B42: =$B$18*A42+$B$12 -> 3644.245 | C42: =$B$26*$A42 -> #DIV/0!
...
